<?xml version="1.0"?>
<robot xmlns:xacro="http://ros.org/wiki/xacro">

  <!-- Import Rviz colors -->
  <xacro:include filename="$(find single_arm_6dof_description)/urdf/single_arm_6dof.material.xacro" />

  <xacro:macro name="single_arm_6dof" params="parent *origin">

  <joint name="origin_to_base_link" type="fixed">
    <xacro:insert_block name="origin" />
    <parent link="${parent}" />
    <child link="base_link" />
    <axis xyz="0 0 1" />
  </joint>

  <link name="base_link">
    <inertial>
      <origin
        xyz="-0.00010098 -0.00035109 0.054127"
        rpy="0 0 0" />
      <mass
        value="2.94316" />
      <inertia
        ixx="0.00082016"
        ixy="3.555E-10"
        ixz="-4.1821E-06"
        iyy="0.00081979"
        iyz="-1.4527E-07"
        izz="0.00035328" />
    </inertial>
    <visual>
      <origin
        xyz="0 0 0"
        rpy="0 0 0" />
      <geometry>
        <mesh
          filename="package://single_arm_6dof_description/meshes/base_link.STL" />
      </geometry>
      <material
        name="grey">
      </material>
    </visual>
    <collision>
      <origin
        xyz="0 0 0"
        rpy="0 0 0" />
      <geometry>
        <mesh
          filename="package://single_arm_6dof_description/meshes/base_link.STL" />
      </geometry>
    </collision>
  </link>

  <joint name="joint1"
    type="revolute">
    <origin
      xyz="0 0 0.1445"
      rpy="0 0 0" />
    <parent
      link="base_link" />
    <child
      link="link1" />
    <axis
      xyz="0 0 1" />
    <limit
      lower="-3.14"
      upper="3.14"
      effort="1"
      velocity="4.8" />
  </joint>

  <link name="link1">
    <inertial>
      <origin
        xyz="3.305E-06 0.0036146 0.029085"
        rpy="0 0 0" />
      <mass
        value="0.93428" />
      <inertia
        ixx="0.00048112"
        ixy="-7.0827E-08"
        ixz="-3.5566E-10"
        iyy="0.00018986"
        iyz="4.1821E-06"
        izz="0.0004948" />
    </inertial>
    <visual>
      <origin
        xyz="0 0 0"
        rpy="0 0 0" />
      <geometry>
        <mesh
          filename="package://single_arm_6dof_description/meshes/link1.STL" />
      </geometry>
      <material
        name="grey">
      </material>
    </visual>
    <collision>
      <origin
        xyz="0 0 0"
        rpy="0 0 0" />
      <geometry>
        <mesh
          filename="package://single_arm_6dof_description/meshes/link1.STL" />
      </geometry>
    </collision>
  </link>


  <joint name="joint2"
    type="revolute">
    <origin
      xyz="0 -0.0684999999999984 0.0315"
      rpy="1.5707963267949 0 0" />
    <parent
      link="link1" />
    <child
      link="link2" />
    <axis
      xyz="0 0 1" />
    <limit
      lower="-3.14"
      upper="3.14"
      effort="0"
      velocity="0" />
  </joint>

  <link name="link2">
    <inertial>
      <origin
        xyz="0.17471 2.0582E-07 0.0097884"
        rpy="0 0 0" />
      <mass
        value="1.07602" />
      <inertia
        ixx="0.00054963"
        ixy="-2.1133E-12"
        ixz="3.6733E-07"
        iyy="0.0010834"
        iyz="-4.2672E-10"
        izz="0.00082532" />
    </inertial>
    <visual>
      <origin
        xyz="0 0 0"
        rpy="0 0 0" />
      <geometry>
        <mesh
          filename="package://single_arm_6dof_description/meshes/link2.STL" />
      </geometry>
      <material
        name="grey">
        <color
          rgba="0.792156862745098 0.819607843137255 0.933333333333333 1" />
      </material>
    </visual>
    <collision>
      <origin
        xyz="0 0 0"
        rpy="0 0 0" />
      <geometry>
        <mesh
          filename="package://single_arm_6dof_description/meshes/link2.STL" />
      </geometry>
    </collision>
  </link>

  <joint
    name="joint3"
    type="revolute">
    <origin
      xyz="0.2675 0 -0.0390000000000001"
      rpy="0 0 0" />
    <parent
      link="link2" />
    <child
      link="link3" />
    <axis
      xyz="0 0 -1" />
    <limit
      lower="-3.14"
      upper="3.14"
      effort="0"
      velocity="0" />
  </joint>

  <link name="link3">
    <inertial>
      <origin
        xyz="0.14898 1.9084E-07 -0.006871"
        rpy="0 0 0" />
      <mass
        value="1.00039" />
      <inertia
        ixx="0.00047701"
        ixy="-1.0214E-11"
        ixz="-1.2577E-06"
        iyy="0.00077795"
        iyz="-9.0438E-10"
        izz="0.00054702" />
    </inertial>
    <visual>
      <origin
        xyz="0 0 0"
        rpy="0 0 0" />
      <geometry>
        <mesh
          filename="package://single_arm_6dof_description/meshes/link3.STL" />
      </geometry>
      <material
        name="grey">
        <color
          rgba="0.792156862745098 0.819607843137255 0.933333333333333 1" />
      </material>
    </visual>
    <collision>
      <origin
        xyz="0 0 0"
        rpy="0 0 0" />
      <geometry>
        <mesh
          filename="package://single_arm_6dof_description/meshes/link3.STL" />
      </geometry>
    </collision>
  </link>

  <joint name="joint4"
    type="revolute">
    <origin
      xyz="0.2324 0 0.0390000000000069"
      rpy="0 0 -3.14159265358979" />
    <parent
      link="link3" />
    <child
      link="link4" />
    <axis
      xyz="0 0 1" />
    <limit
      lower="-3.14"
      upper="3.14"
      effort="0"
      velocity="0" />
  </joint>

  <link name="link4">
    <inertial>
      <origin
        xyz="2.7756E-16 0.01039 0.02404"
        rpy="0 0 0" />
      <mass
        value="0.36924" />
      <inertia
        ixx="9.4187E-05"
        ixy="1.3079E-19"
        ixz="-1.4502E-16"
        iyy="4.476E-05"
        iyz="5.3346E-07"
        izz="0.0001027" />
    </inertial>
    <visual>
      <origin
        xyz="0 0 0"
        rpy="0 0 0" />
      <geometry>
        <mesh
          filename="package://single_arm_6dof_description/meshes/link4.STL" />
      </geometry>
      <material
        name="grey">
        <color
          rgba="0.792156862745098 0.819607843137255 0.933333333333333 1" />
      </material>
    </visual>
    <collision>
      <origin
        xyz="0 0 0"
        rpy="0 0 0" />
      <geometry>
        <mesh
          filename="package://single_arm_6dof_description/meshes/link4.STL" />
      </geometry>
    </collision>
  </link>

  <joint name="joint5"
    type="revolute">
    <origin
      xyz="0 0.052 0.0286"
      rpy="1.5707963267949 0 1.5707963267949" />
    <parent
      link="link4" />
    <child
      link="link5" />
    <axis
      xyz="1 0 0" />
    <limit
      lower="-3.14"
      upper="3.14"
      effort="0"
      velocity="0" />
  </joint>

  <link name="link5">
    <inertial>
      <origin
        xyz="0.028614 0.010457 -1.6653E-16"
        rpy="0 0 0" />
      <mass
        value="0.36821" />
      <inertia
        ixx="0.00010133"
        ixy="5.3346E-07"
        ixz="1.4501E-16"
        iyy="4.3878E-05"
        iyz="-9.098E-20"
        izz="9.3658E-05" />
    </inertial>
    <visual>
      <origin
        xyz="0 0 0"
        rpy="0 0 0" />
      <geometry>
        <mesh
          filename="package://single_arm_6dof_description/meshes/link5.STL" />
      </geometry>
      <material
        name="grey">
        <color
          rgba="0.898039215686275 0.917647058823529 0.929411764705882 1" />
      </material>
    </visual>
    <collision>
      <origin
        xyz="0 0 0"
        rpy="0 0 0" />
      <geometry>
        <mesh
          filename="package://single_arm_6dof_description/meshes/link5.STL" />
      </geometry>
    </collision>
  </link>

  <joint
    name="joint6"
    type="revolute">
    <origin
      xyz="0.0330005379381037 0.0549999394444907 0"
      rpy="1.57079632679488 -1.5707963267949 0" />
    <parent
      link="link5" />
    <child
      link="link6" />
    <axis
      xyz="0 0 -1" />
    <limit
      lower="-3.14"
      upper="3.14"
      effort="0"
      velocity="0" />
  </joint>

  <link name="link6">
    <inertial>
      <origin
        xyz="-4.44089209850063E-16 5.37938091368581E-07 -0.00700006055550945"
        rpy="0 0 0" />
      <mass
        value="0.0259770442543706" />
      <inertia
        ixx="2.20534281951167E-06"
        ixy="1.78671012311437E-22"
        ixz="-8.79317315621994E-22"
        iyy="2.20534281951168E-06"
        iyz="2.32583060538047E-20"
        izz="3.9777349014505E-06" />
    </inertial>
    <visual>
      <origin
        xyz="0 0 0"
        rpy="0 0 0" />
      <geometry>
        <mesh
          filename="package://single_arm_6dof_description/meshes/link6.STL" />
      </geometry>
      <material
        name="grey">
        <color
          rgba="1 1 1 1" />
      </material>
    </visual>
    <collision>
      <origin
        xyz="0 0 0"
        rpy="0 0 0" />
      <geometry>
        <mesh
          filename="package://single_arm_6dof_description/meshes/link6.STL" />
      </geometry>
    </collision>
  </link>

  </xacro:macro>
</robot>
