<?xml version="1.0"?>
<robot xmlns:xacro="http://ros.org/wiki/xacro">

  <!-- Import Rviz colors -->
  <xacro:include filename="$(find single_arm_6dof_description)/urdf/single_arm_6dof.material.xacro" />

  <xacro:macro name="single_arm_6dof" params="parent *origin">

  <joint name="origin_to_base_link" type="fixed">
    <xacro:insert_block name="origin" />
    <parent link="${parent}" />
    <child link="base_link" />
    <axis xyz="0 0 1" />
  </joint>

  <link name="base_link">
    <inertial>
      <origin
        xyz="-3.4663E-05 -4.5026E-05 0.0084004"
        rpy="0 0 0" />
      <mass
        value="2.94316" />
      <inertia
        ixx="0.0094824"
        ixy="3.555E-10"
        ixz="-4.1821E-06"
        iyy="0.0095713"
        iyz="-9.8398E-08"
        izz="0.018031" />
    </inertial>
    <visual>
      <origin
        xyz="0 0 0"
        rpy="0 0 0" />
      <geometry>
        <mesh
          filename="package://single_arm_6dof_description/meshes/base_link.STL" />
      </geometry>
      <material
        name="grey">
      </material>
    </visual>
    <collision>
      <origin
        xyz="0 0 0"
        rpy="0 0 0" />
      <geometry>
        <mesh
          filename="package://single_arm_6dof_description/meshes/base_link.STL" />
      </geometry>
    </collision>
  </link>

  <joint name="joint1"
    type="revolute">
    <origin
      xyz="0 0 0.1445"
      rpy="0 0 0" />
    <parent
      link="base_link" />
    <child
      link="link1" />
    <axis
      xyz="0 0 1" />
    <limit
      lower="-3.14"
      upper="3.14"
      effort="1"
      velocity="4.8" />
  </joint>

  <link name="link1">
    <inertial>
      <origin
        xyz="3.305E-06 0.0036146 0.029085"
        rpy="0 0 0" />
      <mass
        value="0.93428" />
      <inertia
        ixx="0.00048112"
        ixy="-7.0827E-08"
        ixz="-3.5566E-10"
        iyy="0.00018986"
        iyz="4.1821E-06"
        izz="0.0004948" />
    </inertial>
    <visual>
      <origin
        xyz="0 0 0"
        rpy="0 0 0" />
      <geometry>
        <mesh
          filename="package://single_arm_6dof_description/meshes/link1.STL" />
      </geometry>
      <material
        name="grey">
      </material>
    </visual>
    <collision>
      <origin
        xyz="0 0 0"
        rpy="0 0 0" />
      <geometry>
        <mesh
          filename="package://single_arm_6dof_description/meshes/link1.STL" />
      </geometry>
    </collision>
  </link>


  <joint name="joint2"
    type="revolute">
    <origin
      xyz="0 -0.0685 0.0315"
      rpy="1.5708 0 0" />
    <parent
      link="link1" />
    <child
      link="link2" />
    <axis
      xyz="0 0 1" />
    <limit
      lower="-3.14"
      upper="3.14"
      effort="0"
      velocity="0" />
  </joint>

  <link name="link2">
    <inertial>
      <origin
        xyz="-2.4369E-07 0.18004 0.0061614"
        rpy="0 0 0" />
      <mass
        value="1.07602" />
      <inertia
        ixx="0.00076385"
        ixy="2.1135E-12"
        ixz="4.2672E-10"
        iyy="0.00051784"
        iyz="3.6733E-07"
        izz="0.00050582" />
    </inertial>
    <visual>
      <origin
        xyz="0 0 0"
        rpy="0 0 0" />
      <geometry>
        <mesh
          filename="package://single_arm_6dof_description/meshes/link2.STL" />
      </geometry>
      <material
        name="grey">
        <color
          rgba="0.792156862745098 0.819607843137255 0.933333333333333 1" />
      </material>
    </visual>
    <collision>
      <origin
        xyz="0 0 0"
        rpy="0 0 0" />
      <geometry>
        <mesh
          filename="package://single_arm_6dof_description/meshes/link2.STL" />
      </geometry>
    </collision>
  </link>

  <joint
    name="joint3"
    type="revolute">
    <origin
      xyz="0 0.2675 -0.039"
      rpy="-3.1416 0 3.1416" />
    <parent
      link="link2" />
    <child
      link="link3" />
    <axis
      xyz="0 0 1" />
    <limit
      lower="-3.14"
      upper="3.14"
      effort="0"
      velocity="0" />
  </joint>

  <link name="link3">
    <inertial>
      <origin
        xyz="2.2281E-07 0.15321 0.0030804"
        rpy="0 0 0" />
      <mass
        value="1.00039" />
      <inertia
        ixx="0.00058978"
        ixy="-1.0211E-11"
        ixz="9.0438E-10"
        iyy="0.000451"
        iyz="1.2577E-06"
        izz="0.00035885" />
    </inertial>
    <visual>
      <origin
        xyz="0 0 0"
        rpy="0 0 0" />
      <geometry>
        <mesh
          filename="package://single_arm_6dof_description/meshes/link3.STL" />
      </geometry>
      <material
        name="grey">
        <color
          rgba="0.792156862745098 0.819607843137255 0.933333333333333 1" />
      </material>
    </visual>
    <collision>
      <origin
        xyz="0 0 0"
        rpy="0 0 0" />
      <geometry>
        <mesh
          filename="package://single_arm_6dof_description/meshes/link3.STL" />
      </geometry>
    </collision>
  </link>

  <joint name="joint4"
    type="revolute">
    <origin
      xyz="0 0.2324 -0.039"
      rpy="-3.1416 0 1.5708" />
    <parent
      link="link3" />
    <child
      link="link4" />
    <axis
      xyz="0 0 1" />
    <limit
      lower="-3.14"
      upper="3.14"
      effort="0"
      velocity="0" />
  </joint>

  <link name="link4">
    <inertial>
      <origin
        xyz="0.01039 -1.3878E-16 0.02404"
        rpy="0 0 0" />
      <mass
        value="0.36924" />
      <inertia
        ixx="4.476E-05"
        ixy="-1.095E-19"
        ixz="5.3346E-07"
        iyy="9.4187E-05"
        iyz="1.4501E-16"
        izz="0.0001027" />
    </inertial>
    <visual>
      <origin
        xyz="0 0 0"
        rpy="0 0 0" />
      <geometry>
        <mesh
          filename="package://single_arm_6dof_description/meshes/link4.STL" />
      </geometry>
      <material
        name="grey">
        <color
          rgba="0.792156862745098 0.819607843137255 0.933333333333333 1" />
      </material>
    </visual>
    <collision>
      <origin
        xyz="0 0 0"
        rpy="0 0 0" />
      <geometry>
        <mesh
          filename="package://single_arm_6dof_description/meshes/link4.STL" />
      </geometry>
    </collision>
  </link>

  <joint name="joint5"
    type="revolute">
    <origin
      xyz="0.052 0 0.0286"
      rpy="0 1.5708 0" />
    <parent
      link="link4" />
    <child
      link="link5" />
    <axis
      xyz="0 0 1" />
    <limit
      lower="-3.14"
      upper="3.14"
      effort="0"
      velocity="0" />
  </joint>

  <link name="link5">
    <inertial>
      <origin
        xyz="-0.010457 8.3267E-17 0.028614"
        rpy="0 0 0" />
      <mass
        value="0.36821" />
      <inertia
        ixx="4.3878E-05"
        ixy="-1.249E-19"
        ixz="-5.3346E-07"
        iyy="9.3658E-05"
        iyz="-1.4501E-16"
        izz="0.00010133" />
    </inertial>
    <visual>
      <origin
        xyz="0 0 0"
        rpy="0 0 0" />
      <geometry>
        <mesh
          filename="package://single_arm_6dof_description/meshes/link5.STL" />
      </geometry>
      <material
        name="grey">
        <color
          rgba="0.898039215686275 0.917647058823529 0.929411764705882 1" />
      </material>
    </visual>
    <collision>
      <origin
        xyz="0 0 0"
        rpy="0 0 0" />
      <geometry>
        <mesh
          filename="package://single_arm_6dof_description/meshes/link5.STL" />
      </geometry>
    </collision>
  </link>

  <joint
    name="joint6"
    type="revolute">
    <origin
      xyz="-0.055 0 0.033001"
      rpy="0 -1.5708 0" />
    <parent
      link="link5" />
    <child
      link="link6" />
    <axis
      xyz="0 0 1" />
    <limit
      lower="-3.14"
      upper="3.14"
      effort="0"
      velocity="0" />
  </joint>

  <link name="link6">
    <inertial>
      <origin
        xyz="-5.3794E-07 4.1633E-16 0.0070001"
        rpy="0 0 0" />
      <mass
        value="0.025977" />
      <inertia
        ixx="2.2053E-06"
        ixy="2.5014E-22"
        ixz="-1.4272E-22"
        iyy="2.2053E-06"
        iyz="-1.2285E-22"
        izz="3.9777E-06" />
    </inertial>
    <visual>
      <origin
        xyz="0 0 0"
        rpy="0 0 0" />
      <geometry>
        <mesh
          filename="package://single_arm_6dof_description/meshes/link6.STL" />
      </geometry>
      <material
        name="grey">
        <color
          rgba="1 1 1 1" />
      </material>
    </visual>
    <collision>
      <origin
        xyz="0 0 0"
        rpy="0 0 0" />
      <geometry>
        <mesh
          filename="package://single_arm_6dof_description/meshes/link6.STL" />
      </geometry>
    </collision>
  </link>

  </xacro:macro>
</robot>
